Exception on /view-records/stats/overall [GET]
Traceback (most recent call last):
  File "/home/pugking4/.local/lib/python3.9/site-packages/flask/app.py", line 2190, in wsgi_app
    response = self.full_dispatch_request()
  File "/home/pugking4/.local/lib/python3.9/site-packages/flask/app.py", line 1486, in full_dispatch_request
    rv = self.handle_user_exception(e)
  File "/home/pugking4/.local/lib/python3.9/site-packages/flask/app.py", line 1484, in full_dispatch_request
    rv = self.dispatch_request()
  File "/home/pugking4/.local/lib/python3.9/site-packages/flask/app.py", line 1469, in dispatch_request
    return self.ensure_sync(self.view_functions[rule.endpoint])(**view_args)
  File "/home/pugking4/MaiUtils-Website/flask_app/app.py", line 249, in view_records_stats_overall
    stat.get_stats_data()
  File "/home/pugking4/MaiUtils-Website/flask_app/backend_python/stats.py", line 19, in get_stats_data
    data.append()
TypeError: list.append() takes exactly one argument (0 given)
Exception on /view-records/stats/overall [GET]
Traceback (most recent call last):
  File "/home/pugking4/.local/lib/python3.9/site-packages/flask/app.py", line 2190, in wsgi_app
    response = self.full_dispatch_request()
  File "/home/pugking4/.local/lib/python3.9/site-packages/flask/app.py", line 1486, in full_dispatch_request
    rv = self.handle_user_exception(e)
  File "/home/pugking4/.local/lib/python3.9/site-packages/flask/app.py", line 1484, in full_dispatch_request
    rv = self.dispatch_request()
  File "/home/pugking4/.local/lib/python3.9/site-packages/flask/app.py", line 1469, in dispatch_request
    return self.ensure_sync(self.view_functions[rule.endpoint])(**view_args)
  File "/home/pugking4/MaiUtils-Website/flask_app/app.py", line 249, in view_records_stats_overall
    stat.get_stats_data()
  File "/home/pugking4/MaiUtils-Website/flask_app/backend_python/stats.py", line 19, in get_stats_data
    data.append()
TypeError: list.append() takes exactly one argument (0 given)
Exception on /view-records/stats/overall [GET]
Traceback (most recent call last):
  File "/home/pugking4/.local/lib/python3.9/site-packages/flask/app.py", line 2190, in wsgi_app
    response = self.full_dispatch_request()
  File "/home/pugking4/.local/lib/python3.9/site-packages/flask/app.py", line 1486, in full_dispatch_request
    rv = self.handle_user_exception(e)
  File "/home/pugking4/.local/lib/python3.9/site-packages/flask/app.py", line 1484, in full_dispatch_request
    rv = self.dispatch_request()
  File "/home/pugking4/.local/lib/python3.9/site-packages/flask/app.py", line 1469, in dispatch_request
    return self.ensure_sync(self.view_functions[rule.endpoint])(**view_args)
  File "/home/pugking4/MaiUtils-Website/flask_app/app.py", line 249, in view_records_stats_overall
    stat.get_stats_data()
  File "/home/pugking4/MaiUtils-Website/flask_app/backend_python/stats.py", line 19, in get_stats_data
    data.append()
TypeError: list.append() takes exactly one argument (0 given)
Exception on /view-records/stats/overall [GET]
Traceback (most recent call last):
  File "/home/pugking4/.local/lib/python3.9/site-packages/flask/app.py", line 2190, in wsgi_app
    response = self.full_dispatch_request()
  File "/home/pugking4/.local/lib/python3.9/site-packages/flask/app.py", line 1486, in full_dispatch_request
    rv = self.handle_user_exception(e)
  File "/home/pugking4/.local/lib/python3.9/site-packages/flask/app.py", line 1484, in full_dispatch_request
    rv = self.dispatch_request()
  File "/home/pugking4/.local/lib/python3.9/site-packages/flask/app.py", line 1469, in dispatch_request
    return self.ensure_sync(self.view_functions[rule.endpoint])(**view_args)
  File "/home/pugking4/MaiUtils-Website/flask_app/app.py", line 249, in view_records_stats_overall
    stat.get_stats_data()
  File "/home/pugking4/MaiUtils-Website/flask_app/backend_python/stats.py", line 20, in get_stats_data
    print(len(json.load(f)))
  File "/usr/lib/python3.9/json/__init__.py", line 293, in load
    return loads(fp.read(),
  File "/usr/lib/python3.9/json/__init__.py", line 346, in loads
    return _default_decoder.decode(s)
  File "/usr/lib/python3.9/json/decoder.py", line 337, in decode
    obj, end = self.raw_decode(s, idx=_w(s, 0).end())
  File "/usr/lib/python3.9/json/decoder.py", line 355, in raw_decode
    raise JSONDecodeError("Expecting value", s, err.value) from None
json.decoder.JSONDecodeError: Expecting value: line 1 column 1 (char 0)
Exception on /view-records/stats/overall [GET]
Traceback (most recent call last):
  File "/home/pugking4/.local/lib/python3.9/site-packages/flask/app.py", line 2190, in wsgi_app
    response = self.full_dispatch_request()
  File "/home/pugking4/.local/lib/python3.9/site-packages/flask/app.py", line 1486, in full_dispatch_request
    rv = self.handle_user_exception(e)
  File "/home/pugking4/.local/lib/python3.9/site-packages/flask/app.py", line 1484, in full_dispatch_request
    rv = self.dispatch_request()
  File "/home/pugking4/.local/lib/python3.9/site-packages/flask/app.py", line 1469, in dispatch_request
    return self.ensure_sync(self.view_functions[rule.endpoint])(**view_args)
  File "/home/pugking4/MaiUtils-Website/flask_app/app.py", line 249, in view_records_stats_overall
    stat.get_stats_data()
  File "/home/pugking4/MaiUtils-Website/flask_app/backend_python/stats.py", line 20, in get_stats_data
    print(len(f).read())
TypeError: object of type '_io.TextIOWrapper' has no len()
